Workbook

Sheet Calendar
A1: Flowline - 30-Day Social Media Content Calendar
A2: Day 1 = Monday 2 November 2026. Goal: follower growth and reach. All times IST. Edit only the Status and Notes columns; the rest is the approved plan.
A4: Day | B4: Week | C4: Date | D4: Day | E4: Platform | F4: Pillar | G4: Format | H4: Hook (first line) | I4: Caption | J4: CTA | K4: Hashtags | L4: Time (IST) | M4: Status | N4: Notes
A5: 1 | B5: W1 | C5: 46328 | D5: Mon | E5: LinkedIn | F5: Educate | G5: Text + process diagram image | H5: Most ops teams don't have a workflow problem. They have a handoff problem. | I5: Every delay we audit traces back to the same three gaps: work leaves a tool, waits for a human, and re-enters a different tool. Map those three handoffs before you buy another subscription. The diagram shows the two that cost the most hours in a 50-200 person company. | J5: Which handoff breaks first in your team? Tell me in the comments. | K5: #RevOps #WorkflowAutomation #ProcessImprovement #B2BSaaS | L5: 9:00 AM | M5: Not started
B6: W1 | C6: 46328 | D6: Mon | E6: Instagram | F6: Educate | G6: Carousel, 8 slides | H6: Your team isn't slow. Your handoffs are. | I6: Swipe for the three handoff gaps we find in almost every ops audit - and the 10-minute fix for each one. Slide 6 is the one nobody wants to hear. Save this for your next sprint planning. | J6: Save it and send it to the ops person who needs it. | K6: #WorkflowAutomation #RevOps #OpsManager #ProcessImprovement #NoCode #B2BSaaS #OpsLife #AutomationTips | L6: 12:30 PM | M6: Not started
A7: 2 | B7: W1 | C7: 46329 | D7: Tue | E7: LinkedIn | F7: Point of view | G7: Text only | H7: Unpopular opinion: your automation stack is why your team feels slow. | I7: Every tool you add is another place work can get stuck. We have seen 40-person ops teams running nine tools to do what two could. Speed comes from fewer, better-connected steps - not from more subscriptions. Cut one tool this quarter and watch what happens to your cycle time. | J7: Agree or disagree? I reply to every comment. | K7: #SaaS #RevOps #Automation #B2B #OperationsManagement | L7: 8:30 AM | M7: Not started
B8: W1 | C8: 46329 | D8: Tue | E8: Instagram | F8: Point of view | G8: Reel, 30s talking head | H8: POV: your Monday report takes four hours and is out of date when it lands. | I8: If your report is a screenshot of last week, it is a museum piece, not a decision tool. Build the pipeline once and let the number update itself. That is the whole difference between reporting and monitoring. | J8: Follow for one ops fix a day this month. | K8: #OpsLife #WorkflowAutomation #RevOps #Productivity #B2BSaaS #NoCode #AutomationTips | L8: 7:30 PM | M8: Not started
A9: 3 | B9: W1 | C9: 46330 | D9: Wed | E9: LinkedIn | F9: Proof | G9: Document carousel (PDF), 6 pages | H9: A 6-hour weekly report became 11 minutes. Same data, same team. | I9: The workflow: intake form, auto-dedupe, Slack approval, live dashboard. Three steps removed, nothing added, no new headcount. Page 4 shows the exact builder setup. Names and numbers shared with the customer's permission. | J9: Comment 'PLAYBOOK' and I will send the full workflow map. | K9: #CustomerStory #RevOps #WorkflowAutomation #B2BSaaS | L9: 9:00 AM | M9: Not started
B10: W1 | C10: 46330 | D10: Wed | E10: Instagram | F10: Proof | G10: Carousel, 6 slides | H10: 6 hours -> 11 minutes. Same data. Same team. | I10: A 60-person logistics company rebuilt one weekly report and got 11 hours back per week. Slide 4 has the before/after workflow. The fix was not a new tool - it was deleting three steps. | J10: Save this and show it to whoever owns your Monday report. | K10: #CaseStudy #WorkflowAutomation #OpsManager #ProcessImprovement #B2BSaaS #RevOps #BusinessGrowth | L10: 12:30 PM | M10: Not started
A11: 4 | B11: W1 | C11: 46331 | D11: Thu | E11: LinkedIn | F11: Product in action | G11: Screen-recording video, 45s | H11: You can build this approval chain in 8 minutes. No engineer required. | I11: Four steps, one builder, zero code: form submitted, request routed to the right owner, reminder after 24 hours, record logged automatically. We record the timer so you can see how long it actually takes. | J11: Book a 15-minute walkthrough - link in the first comment. | K11: #NoCode #WorkflowAutomation #ProductDemo #B2BSaaS | L11: 8:30 AM | M11: Not started
B12: W1 | C12: 46331 | D12: Thu | E12: Instagram | F12: Product in action | G12: Reel, 20s screen recording | H12: Watch a 4-step approval chain build itself in 20 seconds. | I12: No drag-and-drop montage. This is the real build, sped up 4x. The reminder rule on the last step is the part people forget, and it is the part that saves the SLA. | J12: Follow for the full build series this month. | K12: #NoCode #AutomationTips #WorkflowAutomation #OpsLife #B2BSaaS #TechTeams #Productivity | L12: 7:30 PM | M12: Not started
A13: 5 | B13: W1 | C13: 46332 | D13: Fri | E13: Instagram | F13: Community | G13: Single image + story poll | H13: Be honest: how many tabs do you have open right now? | I13: We asked our community and the median answer was 31. Tab sprawl is usually a symptom of a process nobody documented. Tell me your number - no judgement, I am at 24 today. | J13: Vote in the story poll and drop your number in the comments. | K13: #OpsLife #WorkflowAutomation #Productivity #WorkSmarter #B2BSaaS #TechTeams | L13: 6:30 PM | M13: Not started
A14: 6 | B14: W1 | C14: 46333 | D14: Sat | E14: Stories + engagement | F14: Community | G14: 3 stories, no feed post | H14: No feed post today - engagement sprint. | I14: Three stories: a 60-second tip, a poll on reporting pain, a behind-the-scenes shot of the build. Then 20 minutes commenting on 15 posts from target accounts and replying to every comment from this week. | J14: Reply to every DM within 24 hours. | K14: - | L14: 11:00 AM | M14: Not started
A15: 7 | B15: W1 | C15: 46334 | D15: Sun | E15: Planning day | F15: Community | G15: No publishing | H15: Week 1 review + Week 2 batch. | I15: Pull the numbers into the tracker: reach, saves, profile visits, follower delta. Note the two best hooks and reuse their structure next week. Batch-shoot next week's carousels in one 90-minute block. | J15: Ship Week 2 by Monday 8 AM. | K15: - | L15: 7:00 PM | M15: Not started
A16: 8 | B16: W2 | C16: 46335 | D16: Mon | E16: LinkedIn | F16: Educate | G16: Text + 3-question checklist | H16: The 3-question test we run before automating anything. | I16: 1. Does this step happen more than 10 times a month? 2. Is the rule the same every time? 3. Does a human add judgement here, or just keystrokes? Two yeses and it is a candidate. If question 3 is judgement, automate the handoff, not the decision. | J16: Which of your processes fails question 3? Tell me below. | K16: #ProcessImprovement #RevOps #WorkflowAutomation #OperationsManagement | L16: 9:00 AM | M16: Not started
B17: W2 | C17: 46335 | D17: Mon | E17: Instagram | F17: Educate | G17: Carousel, 7 slides | H17: Steal our 3-question automation test. | I17: Before you automate anything, run this test. Most teams automate the wrong step first, then blame the tool. Swipe for the test, the two failure patterns, and a worked example from a support team. | J17: Save this for your next automation planning session. | K17: #WorkflowAutomation #AutomationTips #OpsManager #NoCode #ProcessImprovement #B2BSaaS #OpsLife | L17: 12:30 PM | M17: Not started
A18: 9 | B18: W2 | C18: 46336 | D18: Tue | E18: LinkedIn | F18: Point of view | G18: Text only | H18: If your ops hire spends 60% of the week moving data, you hired a human integration layer. | I18: That is not a people problem, it is a design problem. The most expensive automation you never bought is the one you are paying a salary for. Audit the week before you hire again: you may be one workflow away from not needing the role. | J18: What percentage of your week is copy-paste? Honest answers only. | K18: #Hiring #OpsLeader #WorkflowAutomation #B2BSaaS #RevOps | L18: 8:30 AM | M18: Not started
B19: W2 | C19: 46336 | D19: Tue | E19: Instagram | F19: Point of view | G19: Reel, 25s | H19: If your ops hire is a human copy-paste machine, this one is for you. | I19: Two numbers tell you whether to hire or automate: how many times a week the task repeats, and how many minutes each repeat takes. Above 40 repeats a month, automate first. Below that, hire or document. | J19: Send this to the person who owns your hiring plan. | K19: #OpsLife #Hiring #WorkflowAutomation #Productivity #B2BSaaS #OpsManager | L19: 7:30 PM | M19: Not started
A20: 10 | B20: W2 | C20: 46337 | D20: Wed | E20: LinkedIn | F20: Proof | G20: Text + customer quote card | H20: Their Monday dashboard used to be a 40-tab spreadsheet. Now it is one Slack message at 7 AM. | I20: Same source data, one pipeline, one delivery channel. The ops lead told us the real win was not the time saved - it was that nobody asks 'what is the status' before 9 AM anymore. That question was costing more than the report. | J20: Comment 'TEMPLATE' and I will DM the reporting pipeline. | K20: #CustomerStory #RevOps #Automation #OperationsManagement | L20: 9:00 AM | M20: Not started
B21: W2 | C21: 46337 | D21: Wed | E21: Instagram | F21: Proof | G21: Carousel, 5 slides | H21: From 40 tabs to one Slack message. | I21: A services team replaced a 40-tab reporting spreadsheet with a single automated message. Slide 3 shows the pipeline, slide 5 shows what they did with the hours they got back. | J21: Save this if your Monday starts with a spreadsheet. | K21: #CaseStudy #WorkflowAutomation #OpsManager #Productivity #B2BSaaS #RevOps #WorkSmarter | L21: 12:30 PM | M21: Not started
A22: 11 | B22: W2 | C22: 46338 | D22: Thu | E22: LinkedIn | F22: Product in action | G22: Feature drop + carousel | H22: Three workflows every ops team should stop building by hand this quarter. | I22: 1. New-hire onboarding checklist routing. 2. Invoice approval above a threshold. 3. Weekly status roll-up across teams. Each one is a 20-minute build and each one removes a recurring 2-4 hour manual task. Templates are in the carousel. | J22: Comment 'TEMPLATE' for all three, ready to import. | K22: #NoCode #WorkflowAutomation #OpsLeader #B2BSaaS | L22: 8:30 AM | M22: Not started
B23: W2 | C23: 46338 | D23: Thu | E23: Instagram | F23: Product in action | G23: Reel, 30s list video | H23: 3 workflows to stop doing by hand this quarter. | I23: Onboarding checklists, invoice approvals, weekly roll-ups. Every one of these is a recurring 2-4 hour task that does not need a human in the middle. Build once, stop thinking about it. | J23: Save this list and pick one for next week. | K23: #AutomationTips #WorkflowAutomation #OpsLife #NoCode #B2BSaaS #Productivity #TechTeams | L23: 7:30 PM | M23: Not started
A24: 12 | B24: W2 | C24: 46339 | D24: Fri | E24: Instagram | F24: Community | G24: Single image, comment prompt | H24: Drop your most annoying manual task below. I will map it in the replies. | I24: I will reply to every single one with a two-step fix - no pitch, no form. Last time we did this we mapped 34 tasks and 11 of them were the same task in different words. That is the pattern worth seeing. | J24: Comment your task. I answer all of them by Sunday. | K24: #OpsLife #WorkflowAutomation #AskMeAnything #B2BSaaS #Productivity #TechTeams | L24: 6:30 PM | M24: Not started
A25: 13 | B25: W2 | C25: 46340 | D25: Sat | E25: Stories + engagement | F25: Community | G25: 3 stories, no feed post | H25: Answering the task maps from yesterday's comments. | I25: Story 1: three of the task maps as screenshots. Story 2: poll - which should we turn into a full teardown. Story 3: repost the best community reply. Then a 20-minute comment sprint. | J25: Reply to every comment within 2 hours. | K25: - | L25: 11:00 AM | M25: Not started
A26: 14 | B26: W2 | C26: 46341 | D26: Sun | E26: Planning day | F26: Community | G26: No publishing | H26: Week 2 review + Week 3 batch. | I26: Check which pillar produced the most saves and the most profile visits - they are rarely the same. Double down on the winner for Week 4. Confirm all customer approvals before anything ships. | J26: Ship Week 3 by Monday 8 AM. | K26: - | L26: 7:00 PM | M26: Not started
A27: 15 | B27: W3 | C27: 46342 | D27: Mon | E27: LinkedIn | F27: Educate | G27: Text + template image | H27: How to write an SOP your team will actually follow. | I27: Six lines, no paragraphs: trigger, owner, input, decision rule, output, escalation. If your SOP needs a table of contents, it will not be read. Screenshot the template and rewrite your worst SOP with it this week. | J27: Want the fillable version? Comment 'SOP'. | K27: #ProcessImprovement #OperationsManagement #OpsLeader #B2BSaaS | L27: 9:00 AM | M27: Not started
B28: W3 | C28: 46342 | D28: Mon | E28: Instagram | F28: Educate | G28: Carousel, 6 slides | H28: The 6-line SOP template nobody taught you. | I28: Trigger, owner, input, decision rule, output, escalation. That is the whole document. Swipe for a filled-in example and the three phrases that make an SOP useless. | J28: Save this and rewrite one SOP today. | K28: #ProcessImprovement #OpsManager #WorkflowAutomation #OpsLife #B2BSaaS #AutomationTips | L28: 12:30 PM | M28: Not started
A29: 16 | B29: W3 | C29: 46343 | D29: Tue | E29: LinkedIn | F29: Point of view | G29: Text only | H29: AI did not fix your process. It made your bad process faster. | I29: If the inputs are messy and the approval rules are unclear, a model will confidently produce the wrong answer at scale. Automate the boring, deterministic parts first. Save the judgement calls for humans and the models will have something clean to work with. | J29: Where has AI made a process worse for you? Genuinely curious. | K29: #AI #WorkflowAutomation #RevOps #B2BSaaS #ProcessImprovement | L29: 8:30 AM | M29: Not started
B30: W3 | C30: 46343 | D30: Tue | E30: Instagram | F30: Point of view | G30: Reel, 30s talking head | H30: Automating a broken process just breaks it faster. | I30: The order matters: clean the process, document the rules, then automate. Skip step one and you are paying for speed you cannot use. Three signs your process is not ready - the second one is the most common. | J30: Follow for the teardown on Friday. | K30: #AI #WorkflowAutomation #OpsLife #Productivity #B2BSaaS #AutomationTips | L30: 7:30 PM | M30: Not started
A31: 17 | B31: W3 | C31: 46344 | D31: Wed | E31: LinkedIn | F31: Proof | G31: Document carousel, 5 pages | H31: Approval time went from 4 days to 6 hours. The only change was where the approval lived. | I31: It moved out of email and into the workflow where the request already existed. No new policy, no new headcount, no training deck. Page 3 shows the before/after routing. Most approval delays are not decisions, they are search problems. | J31: Comment 'ROUTING' and I will send the diagram. | K31: #CustomerStory #RevOps #WorkflowAutomation #OperationsManagement | L31: 9:00 AM | M31: Not started
B32: W3 | C32: 46344 | D32: Wed | E32: Instagram | F32: Proof | G32: Carousel, 5 slides | H32: 4 days -> 6 hours. Same approvers. Same rules. | I32: Nothing about the decision changed. Only where the decision lived. Swipe for the routing map and the one setting that did most of the work. | J32: Save this for your next approval bottleneck. | K32: #CaseStudy #WorkflowAutomation #OpsManager #ProcessImprovement #B2BSaaS #RevOps #Productivity | L32: 12:30 PM | M32: Not started
A33: 18 | B33: W3 | C33: 46345 | D33: Thu | E33: LinkedIn | F33: Product in action | G33: Feature drop + 40s demo | H33: New this week: conditional logic in approvals. | I33: Route by amount, team, region or any field you already collect. Above 5 lakh rupees goes to finance plus a director; below it, one approver. No more 'who signs off on this' threads. Built for the requests that keep slipping through. | J33: See it in the demo - link in the first comment. | K33: #ProductUpdate #NoCode #WorkflowAutomation #B2BSaaS | L33: 8:30 AM | M33: Not started
B34: W3 | C34: 46345 | D34: Thu | E34: Instagram | F34: Product in action | G34: Reel, 20s demo | H34: One rule. Every request routed correctly. | I34: Set the threshold once and every request routes itself. This is the feature our ops customers asked for most - because approval chains break at the edges, not in the middle. | J34: Follow for the next feature drop. | K34: #NoCode #AutomationTips #WorkflowAutomation #OpsLife #B2BSaaS #TechTeams | L34: 7:30 PM | M34: Not started
A35: 19 | B35: W3 | C35: 46346 | D35: Fri | E35: Instagram | F35: Community | G35: Carousel game, 4 slides | H35: Two truths and a lie about workflow automation. | I35: Slide 1 has three claims. Slide 4 has the answer. Most people get it wrong because the lie is the one that sounds most reasonable. Tell me your guess before you swipe. | J35: Comment your guess - 1, 2 or 3. | K35: #OpsLife #WorkflowAutomation #SaaSCommunity #B2BSaaS #Productivity #TechTeams | L35: 6:30 PM | M35: Not started
A36: 20 | B36: W3 | C36: 46347 | D36: Sat | E36: Stories + engagement | F36: Community | G36: 3 stories, no feed post | H36: Behind the scenes: how we build a carousel in 40 minutes. | I36: Story 1: the outline. Story 2: the design pass. Story 3: the checklist we use before publishing. Then a comment sprint on 15 posts from people who engaged this week. | J36: Reply to every story reaction. | K36: - | L36: 11:00 AM | M36: Not started
A37: 21 | B37: W3 | C37: 46348 | D37: Sun | E37: Planning day | F37: Community | G37: No publishing | H37: Week 3 review + Week 4 batch. | I37: Rank every post by saves per reach, not by likes. Kill the two formats that underperformed twice. Pre-write the Week 4 captions so the last week is publishing only. | J37: Ship Week 4 by Monday 8 AM. | K37: - | L37: 7:00 PM | M37: Not started
A38: 22 | B38: W4 | C38: 46349 | D38: Mon | E38: LinkedIn | F38: Educate | G38: Text + agenda template | H38: The 30-minute weekly ops review agenda that replaced our 90-minute one. | I38: 1. Numbers against plan, five minutes. 2. One blocked handoff, ten minutes. 3. One decision, ten minutes. 4. Owner and date for each action, five minutes. No status round-robin - the dashboard already did that. | J38: What would you cut from your current agenda? | K38: #OperationsManagement #OpsLeader #ProcessImprovement #B2BSaaS | L38: 9:00 AM | M38: Not started
B39: W4 | C39: 46349 | D39: Mon | E39: Instagram | F39: Educate | G39: Carousel, 6 slides | H39: Our 30-minute weekly ops review, slide by slide. | I39: Four agenda items, one owner each, zero status updates. Swipe for the exact agenda, the three things we banned from the meeting, and how we keep it to 30 minutes. | J39: Save this and try it next Monday. | K39: #OpsManager #ProcessImprovement #Productivity #OpsLife #B2BSaaS #WorkSmarter | L39: 12:30 PM | M39: Not started
A40: 23 | B40: W4 | C40: 46350 | D40: Tue | E40: LinkedIn | F40: Point of view | G40: Text only | H40: Nobody wants a dashboard. They want to stop being asked 'what is the status?'. | I40: Dashboards answer a question you already had. What people actually want is fewer interruptions and a system that tells them when something is off. Build for the notification, not the chart. If your dashboard needs a weekly meeting to be read, it is not working. | J40: How many times were you asked for a status update today? | K40: #RevOps #OpsLeader #WorkflowAutomation #B2BSaaS #Productivity | L40: 8:30 AM | M40: Not started
B41: W4 | C41: 46350 | D41: Tue | E41: Instagram | F41: Point of view | G41: Reel, 25s | H41: 'What is the status?' is a design failure, not a question. | I41: Every status question is a signal that information is trapped somewhere a person cannot see. Three ways to kill the question permanently - the third one takes ten minutes to set up. | J41: Send this to whoever pings you for updates. | K41: #OpsLife #Productivity #WorkflowAutomation #RevOps #B2BSaaS #TechTeams | L41: 7:30 PM | M41: Not started
...

Sheet Overview
A1: Flowline - 30-Day Social Media Content Strategy
A2: November 2026 calendar | Goal: follower growth and reach | Prepared 29 October 2026
A4: Brand | B4: Flowline - AI workflow automation for operations teams (B2B SaaS, 50-500 person companies)
A5: Platforms | B5: LinkedIn (page + founder profile) and Instagram (business account)
A6: Campaign window | B6: 2 November - 1 December 2026 - Day 1 is Monday 2 November 2026
A7: Primary goal | B7: Follower growth and reach
A8: Secondary goals | B8: Profile visits, saves and shares, inbound DMs
A9: Audience | B9: Ops and RevOps leads at 50-500 person B2B companies, plus founders of 20-50 person companies
A10: Positioning line | B10: "Flowline removes the handoffs, not the people."
A12: PLAN AT A GLANCE
A13: Total rows in the calendar | B13: =COUNTA(Calendar!E5:E52) -> 48
A14: LinkedIn posts | B14: =COUNTIF(Calendar!E5:E52,"LinkedIn") -> 18
A15: Instagram posts | B15: =COUNTIF(Calendar!E5:E52,"Instagram") -> 22
A16: Weekend story / engagement blocks | B16: =COUNTIF(Calendar!E5:E52,"Stories + engagement")+COUNTIF(Calendar!E5:E52,"Planning day") -> 8
A17: Posts marked Published | B17: =COUNTIF(Calendar!M5:M52,"Published") -> 0
A18: Posts still Not started | B18: =COUNTIF(Calendar!M5:M52,"Not started") -> 48
A20: CONTENT PILLAR MIX (live from the Calendar sheet)
A21: Pillar | B21: Feed posts | C21: Share of feed posts | D21: Target share
A22: Educate | B22: =COUNTIFS(Calendar!$F$5:$F$52,"Educate",Calendar!$E$5:$E$52,"<>Stories + engagement",Calendar!$E$5:$E$52,"<>Planning day") -> 10 | C22: =IFERROR(B22/($B$14+$B$15),0) -> 0.25 | D22: 0.25
A23: Point of view | B23: =COUNTIFS(Calendar!$F$5:$F$52,"Point of view",Calendar!$E$5:$E$52,"<>Stories + engagement",Calendar!$E$5:$E$52,"<>Planning day") -> 10 | C23: =IFERROR(B23/($B$14+$B$15),0) -> 0.25 | D23: 0.25
A24: Proof | B24: =COUNTIFS(Calendar!$F$5:$F$52,"Proof",Calendar!$E$5:$E$52,"<>Stories + engagement",Calendar!$E$5:$E$52,"<>Planning day") -> 8 | C24: =IFERROR(B24/($B$14+$B$15),0) -> 0.2 | D24: 0.2
A25: Product in action | B25: =COUNTIFS(Calendar!$F$5:$F$52,"Product in action",Calendar!$E$5:$E$52,"<>Stories + engagement",Calendar!$E$5:$E$52,"<>Planning day") -> 8 | C25: =IFERROR(B25/($B$14+$B$15),0) -> 0.2 | D25: 0.2
A26: Community | B26: =COUNTIFS(Calendar!$F$5:$F$52,"Community",Calendar!$E$5:$E$52,"<>Stories + engagement",Calendar!$E$5:$E$52,"<>Planning day") -> 4 | C26: =IFERROR(B26/($B$14+$B$15),0) -> 0.1 | D26: 0.1
A27: Total | B27: =SUM(B22:B26) -> 40 | C27: =SUM(C22:C26) -> 1 | D27: =SUM(D22:D26) -> 1
A29: HOW TO USE THIS WORKBOOK
A30: - Calendar - every post for all 30 days: platform, pillar, format, hook, caption, CTA, hashtag set and scheduled time.
A31: - Pillars - what each pillar is for, its target share, formats and example topics.
A32: - Hooks and CTAs - the reusable formulas every caption in the calendar is built from.
A33: - Hashtags - the five clusters and the rotation rules (Instagram 8-12 in the first comment, LinkedIn 3-5 at the end).
A34: - Posting Times - the day-by-day IST windows for both platforms and how to validate them in week one.
A35: - Tracker - the monthly scorecard: enter your October baseline, set targets, log actuals; variance and status calculate.
A36: - Yellow cells are the only cells you should type in: Status and Notes on the Calendar, Baseline and Actual on the Tracker.

Sheet Pillars
A1: Content pillars
A2: Five pillars, one per weekday. The split is deliberately flat so no single pillar dominates the feed.
A4: Pillar | B4: Target share | C4: What it does | D4: Formats | E4: Example topics
A5: 1. Educate (how-to) | B5: 25% | C5: Earns saves and shares - the strongest reach signal on both platforms | D5: Instagram carousel, LinkedIn text + diagram, explainer reel | E5: Ops audits, SOP templates, handoff mapping, weekly review agendas
A6: 2. Insight and point of view | B6: 25% | C6: Builds authority and pulls comments from senior buyers | D6: LinkedIn text-only post, talking-head reel, quote card | E6: Contrarian takes on tool sprawl, AI hype, hiring vs automating
A7: 3. Proof (customers and numbers) | B7: 20% | C7: Converts lurkers into followers - real outcomes travel furthest | D7: LinkedIn document carousel, Instagram case-study carousel, testimonial | E7: Before/after hours saved, approval time cut, tool consolidation
A8: 4. Product in action | B8: 20% | C8: Shows the product without pitching - screen recordings beat feature lists | D8: Screen-record reel, feature drop, build-along demo | E8: Approval chains, conditional logic, first 3 workflows to build
A9: 5. Community and engagement | B9: 10% | C9: Feeds the algorithm with comments and gives the audience a voice | D9: Poll, fill-in-the-blank, AMA prompt, story stickers | E9: Manual-task confessions, two truths and a lie, tab-count polls
A11: Pillar rules
A12: - One pillar per post. A post that educates and sells at the same time does neither.
A13: - Rotate formats inside a pillar so the feed never looks repetitive.
A14: - Proof before product: customer stories land Wednesday, product posts Thursday.
A15: - Community posts carry no links and no ask beyond a comment - they exist to generate reply volume.

Sheet Hooks and CTAs
A1: Hook and CTA library
A2: Every caption in the calendar is a variation on one of these. Add new rows as the library grows.
A4: Hook formula | B4: Pattern | C4: Worked example
A5: Contrarian | B5: Most teams think X. It is usually Y. | C5: Most ops teams don't have a workflow problem. They have a handoff problem.
A6: Cost of inaction | B6: Every [period] you wait costs you [unit]. | C6: Every week of manual reporting costs a mid-market team about 11 hours.
A7: Before / after | B7: It used to take X. Now it takes Y. Same team. | C7: It used to take 6 hours. Now it takes 11 minutes. Same team.
A8: Numbered promise | B8: N things that [outcome] - the last one is the one people skip. | C8: 3 things that fix slow approvals - the last one is the one people skip.
A9: Callout | B9: If you are still [old behaviour] in 2026, this is for you. | C9: If your team is still copying data into a spreadsheet every Monday, this is for you.
A10: Confession | B10: I got this wrong for two years. | C10: I got process documentation wrong for two years. Here is what changed.
A11: POV / scenario | B11: POV: [relatable painful moment]. | C11: POV: your Monday report takes four hours and is out of date when it lands.
A12: Question hook | B12: What would you do with [X] hours a week back? | C12: What would your team do with 11 hours a week back?
A13: Myth bust | B13: No, [common belief] is not why [problem]. | C13: No, your team is not slow because they are lazy. It is the handoffs.
A14: Listicle teaser | B14: Steal the [template] we use with every new customer. | C14: Steal the 6-line SOP template we use with every new customer.
A15: Curiosity gap | B15: There is one step in this workflow nobody automates. It is the bottleneck. | C15: There is one step in every approval chain nobody automates. That is the bottleneck.
A16: Direct address | B16: [Role], stop doing [task] by hand. | C16: Ops leads: stop building the same report by hand every week.
A19: CTA LIBRARY
A20: Funnel stage | B20: CTA wording | C20: Where it is used
A21: Reach (saves + shares) | B21: Save this for your next sprint planning. | C21: Bookmark this and send it to the one person who owns this process.
A22: Engagement (comments) | B22: Which one breaks first in your team? Tell me below. | C22: Drop your most annoying manual task - I will map it in the replies.
A23: Growth (follows) | B23: Follow for one ops fix a day this month. | C23: I post one workflow teardown every week - follow if that is useful.
A24: Lead capture (keyword) | B24: Comment 'PLAYBOOK' and I will send the workflow map. | C24: Comment 'TEMPLATE' and I will DM it to you.
A25: Traffic (link) | B25: Full walkthrough is in the first comment. | C25: Link in bio for the 15-minute walkthrough.
A26: Profile visit | B26: More teardowns like this are pinned on my profile. | C26: Everything we publish lives at the link in bio.
A28: - One ask per post, at the end. The middle of the caption earns the right to make the ask.
A29: - Keyword CTAs only work if the asset is sent within 24 hours - batch the DMs twice a day.
A30: - Never ask for a follow in the same post that asks for a comment; save follow asks for reels.
A31: - A save CTA needs a reason: "save this for your next sprint planning" beats "save this".

Sheet Hashtags
A1: Hashtag clusters
A2: Rotate across clusters rather than repeating one set. The branded tag goes on every post.
A4: Cluster | B4: Hashtags | C4: Why it is in the mix
A5: A. Branded (always include 1) | B5: #Flowline #FlowlineOps #WorkflowWednesday | C5: Builds a searchable archive of your own content; use 1-2 per post, never more.
A6: B. Core category (2-3) | B6: #WorkflowAutomation #NoCode #BusinessAutomation #RevOps #SalesOps #AutomationStrategy | C6: Where buyers and practitioners actually browse. Highest intent, lowest volume.
A7: C. Role and topic (2-3) | B7: #OperationsManagement #ProcessImprovement #DigitalTransformation #B2BSaaS #OpsLeader #TechOps | C7: Reaches people by job title and problem, not by product category.
A8: D. Community and engagement (1-2) | B8: #OpsLife #SaaSCommunity #BuildInPublic #TechTeams #FoundersLife | C8: Smaller, chattier tags where comments and shares actually happen.
A9: E. Broad reach (1-2, Instagram only) | B9: #Productivity #BusinessGrowth #StartupIndia #WorkSmarter #Teamwork | C9: High volume, low intent. Use for reach only - skip on LinkedIn.
A11: Rotation rules
A12: - Instagram: 8-12 tags in the first comment (clusters A 1-2, B 2-3, C 2-3, D 1-2, E 1-2).
A13: - LinkedIn: 3-5 tags at the end of the post, clusters A + B + C only - broad reach tags look spammy there.
A14: - Rotate at least 40% of the tags between consecutive posts so the account does not look automated.
A15: - Review monthly: drop any tag that has produced no reach for three posts in a row.
A16: - The exact set for each post is in the Hashtags column of the Calendar sheet.

Sheet Posting Times
A1: Best posting time map
A2: All times IST, India-first audience with a smaller Middle East and UK tail.
A4: Day | B4: LinkedIn window (IST) | C4: Instagram window (IST) | D4: Why
A5: Monday | B5: 9:00-9:30 AM | C5: 12:30-1:00 PM | D5: Monday morning is inbox-triage time on LinkedIn; Instagram peaks over lunch.
A6: Tuesday | B6: 8:30-9:30 AM | C6: 7:30-8:30 PM | D6: Strongest LinkedIn day of the week. Instagram peaks after dinner.
A7: Wednesday | B7: 9:00-10:00 AM | C7: 12:30-1:00 PM | D7: Second-best LinkedIn day; keep carousels here for saves.
A8: Thursday | B8: 8:30-9:30 AM | C8: 7:30-8:30 PM | D8: Product and demo posts land best before the week closes.
A9: Friday | B9: No post | C9: 6:30-7:30 PM | D9: Lowest B2B attention day - use Instagram only, lighter engagement content.
A10: Saturday | B10: No post | C10: 11:00-11:30 AM (stories only) | D10: Stories and polls only. No feed post.
A11: Sunday | B11: No post | C11: 7:00-8:00 PM (stories only) | D11: Planning day. Engagement sprint, no publishing.
A13: Validation notes
A14: - If more than 40% of impressions come from North America, shift evening slots to 7:30-9:30 PM IST (10:00 AM-12:00 PM Eastern).
A15: - LinkedIn: after 7 days check "when your followers are on LinkedIn"; publish 15 minutes before the peak band starts.
A16: - Instagram: use the Insights "most active times" grid and publish 30 minutes before the widest band.
A17: - Test one variable at a time - change the time or the format for a weekday, never both.
A18: - Reels get a second distribution wave 24-48 hours later; carousels live or die in the first two hours.

Sheet Tracker
A1: Monthly scorecard
A2: Enter the October baseline and the actuals each week. Targets, variance and status calculate automatically. Yellow cells are inputs.
A4: Metric | B4: Platform | C4: Baseline (Oct) | D4: 30-day target | E4: Actual | F4: Variance vs target | G4: Status | H4: Target rule
A5: Followers | B5: LinkedIn | C5: 0 | D5: =IF(C5="","",C5*1.2) -> 0 | F5: =IF(E5="","",IFERROR(E5/D5-1,"")) | G5: =IF(E5="","Not logged",IF(E5>=D5,"On track","Behind")) -> Not logged | H5: baseline x 1.20
A6: Followers | B6: Instagram | C6: 0 | D6: =IF(C6="","",C6*1.25) -> 0 | F6: =IF(E6="","",IFERROR(E6/D6-1,"")) | G6: =IF(E6="","Not logged",IF(E6>=D6,"On track","Behind")) -> Not logged | H6: baseline x 1.25
A7: Reach per post | B7: Both | C7: 0 | D7: =IF(C7="","",C7*1.3) -> 0 | F7: =IF(E7="","",IFERROR(E7/D7-1,"")) | G7: =IF(E7="","Not logged",IF(E7>=D7,"On track","Behind")) -> Not logged | H7: baseline x 1.30
A8: Saves per carousel | B8: Instagram | C8: 0 | D8: 40 | F8: =IF(E8="","",IFERROR(E8/D8-1,"")) | G8: =IF(E8="","Not logged",IF(E8>=D8,"On track","Behind")) -> Not logged | H8: fixed at 40
A9: Saves and shares per post | B9: LinkedIn | C9: 0 | D9: =IF(C9="","",C9*1.5) -> 0 | F9: =IF(E9="","",IFERROR(E9/D9-1,"")) | G9: =IF(E9="","Not logged",IF(E9>=D9,"On track","Behind")) -> Not logged | H9: baseline x 1.50
A10: Profile visits | B10: Both | C10: 0 | D10: =IF(C10="","",C10*1.4) -> 0 | F10: =IF(E10="","",IFERROR(E10/D10-1,"")) | G10: =IF(E10="","Not logged",IF(E10>=D10,"On track","Behind")) -> Not logged | H10: baseline x 1.40
A11: Comment rate (comments / reach) | B11: Both | C11: 0 | D11: 0.015 | F11: =IF(E11="","",IFERROR(E11/D11-1,"")) | G11: =IF(E11="","Not logged",IF(E11>=D11,"On track","Behind")) -> Not logged | H11: fixed at 1.50%
A12: Inbound DMs and keyword comments | B12: Both | C12: 0 | D12: 25 | F12: =IF(E12="","",IFERROR(E12/D12-1,"")) | G12: =IF(E12="","Not logged",IF(E12>=D12,"On track","Behind")) -> Not logged | H12: fixed at 25
A14: How to use the scorecard
A15: - Enter the October averages in Baseline before Day 1 - a target without a starting number is an opinion.
A16: - Targets are written as multiples of baseline where the goal is growth, and as absolute numbers where it is a count.
A17: - Log actuals every Sunday, then read the Status column: two "Behind" weeks on the same metric means the format or the hook is wrong, not the effort.
A18: - Rank posts by saves per reach, not by likes - likes measure politeness, saves measure usefulness.
